<?xml version="1.0"?>
<robot name="robot_with_arm">

  <material name="blue">
    <color rgba="0 0 0.8 1"/>
  </material>

  <material name="white">
    <color rgba="1 1 1 1"/>
  </material>

  <link name="base_link">
    <visual>
      <geometry>
        <box size="0.8 0.7 0.1"/>
      </geometry>
      <material name="blue"/>
    </visual>
  </link>

  <link name="front_left_wheel">
    <visual>
      <geometry>
        <cylinder length="0.02" radius="0.0762"/>
      </geometry>
      <origin rpy="0 1.57075 1.57075" xyz="0 0 0"/>
      <material name="white"/>
    </visual>
  </link>

  <joint name="base_to_front_left_wheel" type="continuous">
    <parent link="base_link"/>
    <child link="front_left_wheel"/>
    <origin xyz=".35 .36 -.01"/>
    <axis xyz="0 1 0"/>
  </joint>

  <link name="center_left_wheel">
    <visual>
      <geometry>
        <cylinder length="0.02" radius="0.0762"/>
      </geometry>
      <origin rpy="0 1.57075 1.57075" xyz="0 0 0"/>
      <material name="white"/>
    </visual>
  </link>

  <joint name="base_to_center_left_wheel" type="continuous">
    <parent link="base_link"/>
    <child link="center_left_wheel"/>
    <origin xyz="0 .36 -.01"/>
    <axis xyz="0 1 0"/>
  </joint>

  <link name="rear_left_wheel">
    <visual>
      <geometry>
        <cylinder length="0.02" radius="0.0762"/>
      </geometry>
      <origin rpy="0 1.57075 1.57075" xyz="0 0 0"/>
      <material name="white"/>
    </visual>
  </link>

  <joint name="base_to_rear_left_wheel" type="continuous">
    <parent link="base_link"/>
    <child link="rear_left_wheel"/>
    <origin xyz="-.35 .36 -.01"/>
    <axis xyz="0 1 0"/>
  </joint>

  <link name="front_right_wheel">
    <visual>
      <geometry>
        <cylinder length="0.02" radius="0.0762"/>
      </geometry>
      <origin rpy="0 1.57075 1.57075" xyz="0 0 0"/>
      <material name="white"/>
    </visual>
  </link>

  <joint name="base_to_front_right_wheel" type="continuous">
    <parent link="base_link"/>
    <child link="front_right_wheel"/>
    <origin xyz=".35 -.36 -.01"/>
    <axis xyz="0 1 0"/>
  </joint>

  <link name="center_right_wheel">
    <visual>
      <geometry>
        <cylinder length="0.02" radius="0.0762"/>
      </geometry>
      <origin rpy="0 1.57075 1.57075" xyz="0 0 0"/>
      <material name="white"/>
    </visual>
  </link>

  <joint name="base_to_center_right_wheel" type="continuous">
    <parent link="base_link"/>
    <child link="center_right_wheel"/>
    <origin xyz="0 -.36 -.01"/>
    <axis xyz="0 1 0"/>
  </joint>

  <link name="rear_right_wheel">
    <visual>
      <geometry>
        <cylinder length="0.02" radius="0.0762"/>
      </geometry>
      <origin rpy="0 1.57075 1.57075" xyz="0 0 0"/>
      <material name="white"/>
    </visual>
  </link>

  <joint name="base_to_rear_right_wheel" type="continuous">
    <parent link="base_link"/>
    <child link="rear_right_wheel"/>
    <origin xyz="-.35 -.36 -.01"/>
    <axis xyz="0 1 0"/>
  </joint>
</robot>